Workbook

Sheet Cover
E9: NIKE, Inc. | 3 Statement Model | 8/26/2026 | Joshua Ponce | R9: Color Guide
R11: Blue = Hardcoded Values
R12: Black = Formulas that reference cells within the same sheet
R13: Green = Formulas with cross-sheet references
R16: AI Usage Statement
R17: Built independently; used Claude as a review tool to audit formula logic and refine consistency

Sheet Income statement
A1: Nike Historical & Projected Income Statement
A3: (In millions, except per share data) | D3: 2022A | E3: 2023A | F3: 2024A | G3: 2025A | H3: 2026A | I3: 2027E | J3: 2028E | K3: 2029E | L3: 2030E | M3: 2031E
A4: Revenues | D4: 46710 | E4: 51217 | F4: 51362 | G4: 46309 | H4: 46398 | I4: =H4*(1+D29) -> 47789.94 | J4: =I4*(1+E29) -> 49701.538 | K4: =J4*(1+F29) -> 51192.584 | L4: =K4*(1+G29) -> 52216.435 | M4: =L4*(1+H29) -> 53260.764
A5: Cost of sales | D5: 25231 | E5: 28925 | F5: 28475 | G5: 26519 | H5: 26487 | I5: =I4*D30 -> 26789.446 | J5: =J4*E30 -> 27861.024 | K5: =K4*F30 -> 28696.854 | L5: =L4*G30 -> 29270.792 | M5: =M4*H30 -> 29856.207
A6: Gross profit | D6: 21479 | E6: 22292 | F6: 22887 | G6: 19790 | H6: 19911 | I6: =I4-I5 -> 21000.494 | J6: =J4-J5 -> 21840.514 | K6: =K4-K5 -> 22495.729 | L6: =L4-L5 -> 22945.644 | M6: =M4-M5 -> 23404.557
A7: Demand creation expense | D7: 3850 | E7: 4060 | F7: 4285 | G7: 4689 | H7: 4754 | I7: =I4*D31 -> 4289.9823 | J7: =J4*E31 -> 4461.5816 | K7: =K4*F31 -> 4595.4291 | L7: =L4*G31 -> 4687.3377 | M7: =M4*H31 -> 4781.0844
A8: Operating overhead expense | D8: 10954 | E8: 12317 | F8: 12291 | G8: 11399 | H8: 11360 | I8: =I4*D32 -> 11520.126 | J8: =J4*E32 -> 11980.931 | K8: =K4*F32 -> 12340.359 | L8: =L4*G32 -> 12587.166 | M8: =M4*H32 -> 12838.91
A9: Total selling and administrative expense | D9: 14804 | E9: 16377 | F9: 16576 | G9: 16088 | H9: 16114 | I9: =I7+I8 -> 15810.109 | J9: =J7+J8 -> 16442.513 | K9: =K7+K8 -> 16935.788 | L9: =L7+L8 -> 17274.504 | M9: =M7+M8 -> 17619.994
A10: Interest (income) expense, net | D10: 205 | E10: -6 | F10: -161 | G10: -107 | H10: -50 | I10: =I4*D33 -> -79.330827 | J10: =J4*E33 -> -82.50406 | K10: =K4*F33 -> -84.979182 | L10: =L4*G33 -> -86.678766 | M10: =M4*H33 -> -88.412341
A11: Other (income) expense, net | D11: -181 | E11: -280 | F11: -228 | G11: -76 | H11: -53 | I11: =I4*D34 -> -158.3226 | J11: =J4*E34 -> -164.65551 | K11: =K4*F34 -> -169.59517 | L11: =L4*G34 -> -172.98707 | M11: =M4*H34 -> -176.44682
A12: Income before income taxes | D12: 6651 | E12: 6201 | F12: 6700 | G12: 3885 | H12: 3900 | I12: =I6-I9-I10-I11 -> 5428.039 | J12: =J6-J9-J10-J11 -> 5645.1605 | K12: =K6-K9-K10-K11 -> 5814.5153 | L12: =L6-L9-L10-L11 -> 5930.8056 | M12: =M6-M9-M10-M11 -> 6049.4218
A13: Income tax expense | D13: 605 | E13: 1131 | F13: 1000 | G13: 666 | H13: 792 | I13: =D35*I12 -> 1085.6078 | J13: =E35*J12 -> 1129.0321 | K13: =F35*K12 -> 1162.9031 | L13: =G35*L12 -> 1186.1611 | M13: =H35*M12 -> 1209.8844
A14: NET INCOME | D14: 6046 | E14: 5070 | F14: 5700 | G14: 3219 | H14: 3108 | I14: =I12-I13 -> 4342.4312 | J14: =J12-J13 -> 4516.1284 | K14: =K12-K13 -> 4651.6123 | L14: =L12-L13 -> 4744.6445 | M14: =M12-M13 -> 4839.5374
A16: Earnings per common share:
A17: Basic | D17: 3.83 | E17: 3.27 | F17: 3.76 | G17: 2.17 | H17: 2.1 | I17: =I14/I21 -> 2.9822798 | J17: =J14/J21 -> 3.1521014 | K17: =K14/K21 -> 3.2995588 | L17: =L14/L21 -> 3.4203811 | M17: =M14/M21 -> 3.5456277
A18: Diluted | D18: 3.75 | E18: 3.23 | F18: 3.73 | G18: 2.16 | H18: 2.1 | I18: =$I$14/I22 -> 2.9798633 | J18: =$I$14/J22 -> 3.028411 | K18: =$I$14/K22 -> 3.0777495 | L18: =$I$14/L22 -> 3.1278919 | M18: =$I$14/M22 -> 3.1788512
A20: Weighted Average Shares Outstanding:
A21: Basic | D21: 1578.8 | E21: 1551.6 | F21: 1517.6 | G21: 1484.9 | H21: 1479.8 | I21: =H21*(1+$D$36) -> 1456.0777 | J21: =I21*(1+$D$36) -> 1432.7358 | K21: =J21*(1+$D$36) -> 1409.768 | L21: =K21*(1+$D$36) -> 1387.1684 | M21: =L21*(1+$D$36) -> 1364.9311
A22: Diluted | D22: 1610.8 | E22: 1569.8 | F22: 1529.7 | G22: 1487.6 | H22: 1481 | I22: =H22*(1+$D$36) -> 1457.2585 | J22: =I22*(1+$D$36) -> 1433.8976 | K22: =J22*(1+$D$36) -> 1410.9112 | L22: =K22*(1+$D$36) -> 1388.2932 | M22: =L22*(1+$D$36) -> 1366.0379
A27: Income Statement Assumptions/Drivers
D28: 2027 | E28: 2028 | F28: 2029 | G28: 2030 | H28: 2031
A29: Revenue Growth | D29: 0.03 | E29: 0.04 | F29: 0.03 | G29: 0.02 | H29: 0.02 | I29: Assumed modest revenue bounce-back due to CEO's new "Win Now" plan (Bottom Up Revenue Build that benchmarks against consensus estimates will be added soon)
A30: COGS (% of revenue) | D30: {=SUM($D$5:$H$5/$D$4:$H$4)/COUNT($D$4:$H$4)} -> 0.56056664 | E30: {=SUM($D$5:$H$5/$D$4:$H$4)/COUNT($D$4:$H$4)} -> 0.56056664 | F30: {=SUM($D$5:$H$5/$D$4:$H$4)/COUNT($D$4:$H$4)} -> 0.56056664 | G30: {=SUM($D$5:$H$5/$D$4:$H$4)/COUNT($D$4:$H$4)} -> 0.56056664 | H30: {=SUM($D$5:$H$5/$D$4:$H$4)/COUNT($D$4:$H$4)} -> 0.56056664
A31: Demand Creation (% of revenue) | D31: {=SUM($D$7:$H$7/$D$4:$H$4)/COUNT($D$4:$H$4)} -> 0.089767477 | E31: {=SUM($D$7:$H$7/$D$4:$H$4)/COUNT($D$4:$H$4)} -> 0.089767477 | F31: {=SUM($D$7:$H$7/$D$4:$H$4)/COUNT($D$4:$H$4)} -> 0.089767477 | G31: {=SUM($D$7:$H$7/$D$4:$H$4)/COUNT($D$4:$H$4)} -> 0.089767477 | H31: {=SUM($D$7:$H$7/$D$4:$H$4)/COUNT($D$4:$H$4)} -> 0.089767477
A32: Operating overhead expense (% of revenue) | D32: {=SUM($D$8:$H$8/$D$4:$H$4)/COUNT($D$4:$H$4)} -> 0.24105756 | E32: {=SUM($D$8:$H$8/$D$4:$H$4)/COUNT($D$4:$H$4)} -> 0.24105756 | F32: {=SUM($D$8:$H$8/$D$4:$H$4)/COUNT($D$4:$H$4)} -> 0.24105756 | G32: {=SUM($D$8:$H$8/$D$4:$H$4)/COUNT($D$4:$H$4)} -> 0.24105756 | H32: {=SUM($D$8:$H$8/$D$4:$H$4)/COUNT($D$4:$H$4)} -> 0.24105756
A33: Interest income expense rate (% of revnue) | D33: {=AVERAGE($E$10:$H$10/$E$4:$H$4)} -> -0.0016599901 | E33: {=AVERAGE($E$10:$H$10/$E$4:$H$4)} -> -0.0016599901 | F33: {=AVERAGE($E$10:$H$10/$E$4:$H$4)} -> -0.0016599901 | G33: {=AVERAGE($E$10:$H$10/$E$4:$H$4)} -> -0.0016599901 | H33: {=AVERAGE($E$10:$H$10/$E$4:$H$4)} -> -0.0016599901
A34: Other (income) expense rate (% of revenue) | D34: {=AVERAGE($D$11:$H$11/$D$4:$H$4)} -> -0.0033128856 | E34: {=AVERAGE($D$11:$H$11/$D$4:$H$4)} -> -0.0033128856 | F34: {=AVERAGE($D$11:$H$11/$D$4:$H$4)} -> -0.0033128856 | G34: {=AVERAGE($D$11:$H$11/$D$4:$H$4)} -> -0.0033128856 | H34: {=AVERAGE($D$11:$H$11/$D$4:$H$4)} -> -0.0033128856
A35: Tax Rate | D35: 0.2 | E35: 0.2 | F35: 0.2 | G35: 0.2 | H35: 0.2 | I35: Held flat at approximate Federal Statutory Tax Rate
A36: Share buy-back rate | D36: {=AVERAGE(($E$21:$H$21/$D$21:$G$21)-1)} -> -0.016030723 | E36: {=AVERAGE(($E$21:$H$21/$D$21:$G$21)-1)} -> -0.016030723 | F36: {=AVERAGE(($E$21:$H$21/$D$21:$G$21)-1)} -> -0.016030723 | G36: {=AVERAGE(($E$21:$H$21/$D$21:$G$21)-1)} -> -0.016030723 | H36: {=AVERAGE(($E$21:$H$21/$D$21:$G$21)-1)} -> -0.016030723

Sheet Balance Sheet
A1: Nike Historical and Project Balance Sheet
A3: (In millions, except per share data) | B3: 2022A | C3: 2023A | D3: 2024A | E3: 2025A | F3: 2026A | G3: 2027E | H3: 2028E | I3: 2029E | J3: 2030E | K3: 2031E
A4: ASSETS
A5: Current assets:
A6: Cash and equivalents | B6: 8574 | C6: 7441 | D6: 9860 | E6: 7464 | F6: 7563 | G6: ='Statement of Cashflows'!G$39 -> 8353.6365 | H6: ='Statement of Cashflows'!H$39 -> 8170.9079 | I6: ='Statement of Cashflows'!I$39 -> 6928.632 | J6: ='Statement of Cashflows'!J$39 -> 4104.0543 | K6: ='Statement of Cashflows'!K$39 -> 2592.9752
A7: Short-term investments | B7: 4423 | C7: 3234 | D7: 1722 | E7: 1687 | F7: 1464 | G7: =F7*(1+B53) -> 1826.3174 | H7: =G7*(1+C53) -> 2278.3027 | I7: =H7*(1+D53) -> 2842.1474 | J7: =I7*(1+E53) -> 3545.5349 | K7: =J7*(1+F53) -> 4423
A8: Accounts receivable, net | B8: 4667 | C8: 4131 | D8: 4427 | E8: 4717 | F8: 5931 | G8: ='Income statement'!I4*(B50/365) -> 4404.1124 | H8: ='Income statement'!J4*(C50/365) -> 4580.2769 | I8: ='Income statement'!K4*(D50/365) -> 4717.6852 | J8: ='Income statement'!L4*(E50/365) -> 4812.039 | K8: ='Income statement'!M4*(F50/365) -> 4908.2797
A9: Inventories | B9: 8420 | C9: 8454 | D9: 7519 | E9: 7489 | F9: 7501 | G9: ='Income statement'!I5*(B51/365) -> 7513.9449 | H9: ='Income statement'!J5*(C51/365) -> 7814.5027 | I9: ='Income statement'!K5*(D51/365) -> 8048.9378 | J9: ='Income statement'!L5*(E51/365) -> 8209.9165 | K9: ='Income statement'!M5*(F51/365) -> 8374.1148
A10: Prepaid expenses and other current assets | B10: 2129 | C10: 1942 | D10: 1854 | E10: 2005 | F10: 2144 | G10: =B52*'Income statement'!I4 -> 1998.5556 | H10: =C52*'Income statement'!J4 -> 2078.4978 | I10: =D52*'Income statement'!K4 -> 2140.8527 | J10: =E52*'Income statement'!L4 -> 2183.6698 | K10: =F52*'Income statement'!M4 -> 2227.3432
A11: Total current assets | B11: 28213 | C11: 25202 | D11: 25382 | E11: 23362 | F11: 24603 | G11: =SUM(G6:G10) -> 24096.567 | H11: =SUM(H6:H10) -> 24922.488 | I11: =SUM(I6:I10) -> 24678.255 | J11: =SUM(J6:J10) -> 22855.214 | K11: =SUM(K6:K10) -> 22525.713
A12: Property, plant and equipment, net | B12: 4791 | C12: 5081 | D12: 5000 | E12: 4828 | F12: 4796 | G12: =F12-'Statement of Cashflows'!G22-'Statement of Cashflows'!G7 -> 4772.8227 | H12: =G12-'Statement of Cashflows'!H22-'Statement of Cashflows'!H7 -> 4748.7183 | I12: =H12-'Statement of Cashflows'!I22-'Statement of Cashflows'!I7 -> 4723.8908 | J12: =I12-'Statement of Cashflows'!J22-'Statement of Cashflows'!J7 -> 4698.5667 | K12: =J12-'Statement of Cashflows'!K22-'Statement of Cashflows'!K7 -> 4672.7362
A13: Operating lease right-of-use assets, net | B13: 2926 | C13: 2923 | D13: 2718 | E13: 2712 | F13: 2838 | G13: =B56*'Income statement'!I4 -> 2794.3809 | H13: =C56*'Income statement'!J4 -> 2906.1561 | I13: =D56*'Income statement'!K4 -> 2993.3408 | J13: =E56*'Income statement'!L4 -> 3053.2076 | K13: =F56*'Income statement'!M4 -> 3114.2718
A14: Identifiable intangible assets, net | B14: 286 | C14: 274 | D14: 259 | E14: 259 | F14: 259 | G14: =$F$14 -> 259 | H14: =$F$14 -> 259 | I14: =$F$14 -> 259 | J14: =$F$14 -> 259 | K14: =$F$14 -> 259
A15: Goodwill | B15: 284 | C15: 281 | D15: 240 | E15: 240 | F15: 240 | G15: =$F$15 -> 240 | H15: =$F$15 -> 240 | I15: =$F$15 -> 240 | J15: =$F$15 -> 240 | K15: =$F$15 -> 240
A16: Deferred income taxes and other assets | B16: 3821 | C16: 3770 | D16: 4511 | E16: 5178 | F16: 5674 | G16: =B57*'Income statement'!I4 -> 5593.8125 | H16: =C57*'Income statement'!J4 -> 5817.565 | I16: =D57*'Income statement'!K4 -> 5992.0919 | J16: =E57*'Income statement'!L4 -> 6111.9338 | K16: =F57*'Income statement'!M4 -> 6234.1724
A17: TOTAL ASSETS | B17: 40321 | C17: 37531 | D17: 38110 | E17: 36579 | F17: 38410 | G17: =SUM(G11:G16) -> 37756.583 | H17: =SUM(H11:H16) -> 38893.927 | I17: =SUM(I11:I16) -> 38886.579 | J17: =SUM(J11:J16) -> 37217.923 | K17: =SUM(K11:K16) -> 37045.893
A19: LIABILITIES AND SHAREHOLDERS' EQUITY
A20: Current liabilities:
A21: Current portion of long-term debt | B21: 500 | C21: — | D21: 1000 | E21: — | F21: 2000 | G21: =C71*-1 -> 0 | H21: =D71*-1 -> 0 | I21: =E71*-1 -> 1500 | J21: =F71*-1 -> 0 | K21: =G71*-1 -> 0
A22: Notes payable | B22: 10 | C22: 6 | D22: 6 | E22: — | F22: — | G22: — | H22: — | I22: — | J22: — | K22: —
A23: Accounts payable | B23: 3358 | C23: 2862 | D23: 2851 | E23: 3479 | F23: 3600 | G23: =(B58/365)*'Income statement'!I5 -> 1800.2163 | H23: =(C58/365)*'Income statement'!J5 -> 1872.225 | I23: =(D58/365)*'Income statement'!K5 -> 1928.3917 | J23: =(E58/365)*'Income statement'!L5 -> 1966.9596 | K23: =(F58/365)*'Income statement'!M5 -> 2006.2987
A24: Current portion of operating lease liabilities | B24: 420 | C24: 425 | D24: 477 | E24: 502 | F24: 478 | G24: =B59*'Income statement'!I4 -> 456.09851 | H24: =C59*'Income statement'!J4 -> 474.34245 | I24: =D59*'Income statement'!K4 -> 488.57272 | J24: =E59*'Income statement'!L4 -> 498.34418 | K24: =F59*'Income statement'!M4 -> 508.31106
A25: Accrued liabilities | B25: 6220 | C25: 5723 | D25: 5725 | E25: 5916 | F25: 6092 | G25: =B60*'Income statement'!I4 -> 5882.1325 | H25: =C60*'Income statement'!J4 -> 6117.4178 | I25: =D60*'Income statement'!K4 -> 6300.9403 | J25: =E60*'Income statement'!L4 -> 6426.9591 | K25: =F60*'Income statement'!M4 -> 6555.4983
A26: Income taxes payable | B26: 222 | C26: 240 | D26: 534 | E26: 669 | F26: 377 | G26: =B61*'Income statement'!I14 -> 2252.5566 | H26: =C61*'Income statement'!J14 -> 2342.6588 | I26: =D61*'Income statement'!K14 -> 2412.9386 | J26: =E61*'Income statement'!L14 -> 2461.1974 | K26: =F61*'Income statement'!M14 -> 2510.4213
A27: Total current liabilities | B27: 10730 | C27: 9256 | D27: 10593 | E27: 10566 | F27: 12547 | G27: =SUM(G21:G26) -> 10391.004 | H27: =SUM(H21:H26) -> 10806.644 | I27: =SUM(I21:I26) -> 12630.843 | J27: =SUM(J21:J26) -> 11353.46 | K27: =SUM(K21:K26) -> 11580.529
A28: Long-term debt | B28: 8920 | C28: 8927 | D28: 7903 | E28: 7961 | F28: 5942 | G28: =B73 -> 5942 | H28: =C73 -> 5942 | I28: =D73 -> 4442 | J28: =E73 -> 4442 | K28: =F73 -> 4442
A29: Operating lease liabilities | B29: 2777 | C29: 2786 | D29: 2566 | E29: 2550 | F29: 2613 | G29: =B62*'Income statement'!I4 -> 2630.2534 | H29: =C62*'Income statement'!J4 -> 2735.4635 | I29: =D62*'Income statement'!K4 -> 2817.5274 | J29: =E62*'Income statement'!L4 -> 2873.878 | K29: =F62*'Income statement'!M4 -> 2931.3556
A30: Deferred income taxes and other liabilities | B30: 2613 | C30: 2558 | D30: 2618 | E30: 2289 | F30: 2443 | G30: =B63*'Income statement'!I4 -> 2474.9337 | H30: =C63*'Income statement'!J4 -> 2573.931 | I30: =D63*'Income statement'!K4 -> 2651.1489 | J30: =E63*'Income statement'!L4 -> 2704.1719 | K30: =F63*'Income statement'!M4 -> 2758.2554
A31: Total Long Term Liabilities | B31: =SUM(B28:B30) -> 14310 | C31: =SUM(C28:C30) -> 14271 | D31: =SUM(D28:D30) -> 13087 | E31: =SUM(E28:E30) -> 12800 | F31: =SUM(F28:F30) -> 10998 | G31: =SUM(G28:G30) -> 11047.187 | H31: =SUM(H28:H30) -> 11251.395 | I31: =SUM(I28:I30) -> 9910.6764 | ... K31: =SUM(K28:K30) -> 10131.611
A33: Shareholders' equity:
A34: Class A convertible | B34: — | C34: — | D34: — | E34: — | F34: — | G34: — | H34: — | I34: — | J34: — | K34: —
A35: Class B | B35: 3 | C35: 3 | D35: 3 | E35: 3 | F35: 3 | G35: =$F$35 -> 3 | H35: =$F$35 -> 3 | I35: =$F$35 -> 3 | J35: =$F$35 -> 3 | K35: =$F$35 -> 3
A36: Capital in excess of stated value | B36: 11484 | C36: 12412 | D36: 13409 | E36: 14195 | F36: 15158 | G36: =F36+'Statement of Cashflows'!G9+'Statement of Cashflows'!G30 -> 16412.714 | H36: =G36+'Statement of Cashflows'!H9+'Statement of Cashflows'!H30 -> 17717.617 | I36: =H36+'Statement of Cashflows'!I9+'Statement of Cashflows'!I30 -> 19061.667 | J36: =I36+'Statement of Cashflows'!J9+'Statement of Cashflows'!J30 -> 20432.598 | K36: =J36+'Statement of Cashflows'!K9+'Statement of Cashflows'!K30 -> 21830.947
A37: Accumulated other comprehensive income (loss) | B37: 318 | C37: 231 | D37: 53 | E37: -258 | F37: -141 | G37: =F37+'Statement of Cashflows'!G36 -> -141 | H37: =G37+'Statement of Cashflows'!H36 -> -141 | I37: =H37+'Statement of Cashflows'!I36 -> -141 | J37: =I37+'Statement of Cashflows'!J36 -> -141 | K37: =J37+'Statement of Cashflows'!K36 -> -141
A38: Retained earnings (deficit) | B38: 3476 | C38: 1358 | D38: 965 | E38: -727 | F38: -155 | G38: =F38+'Income statement'!I14+'Statement of Cashflows'!G32+'Statement of Cashflows'!G31 -> 43.677712 | H38: =G38+'Statement of Cashflows'!H31+'Income statement'!J14+'Statement of Cashflows'!H32 -> -743.72822 | I38: =H38+'Statement of Cashflows'!I31+'Income statement'!K14+'Statement of Cashflows'!I32 -> -2578.608 | J38: =I38+'Statement of Cashflows'!J31+'Income statement'!L14+'Statement of Cashflows'!J32 -> -4450.1854 | K38: =J38+'Statement of Cashflows'!K31+'Income statement'!M14+'Statement of Cashflows'!K32 -> -6359.1943
A39: Total shareholders' equity | B39: 15281 | C39: 14004 | D39: 14430 | E39: 13213 | F39: 14865 | G39: =SUM(G34:G38) -> 16318.392 | H39: =SUM(H34:H38) -> 16835.889 | I39: =SUM(I34:I38) -> 16345.059 | J39: =SUM(J34:J38) -> 15844.412 | K39: =SUM(K34:K38) -> 15333.753
A40: TOTAL LIABILITIES AND SHAREHOLDERS' EQUITY | B40: 40321 | C40: 37531 | D40: 38110 | E40: 36579 | F40: 38410 | G40: =G39+SUM(G27:G30) -> 37756.583 | H40: =H39+SUM(H27:H30) -> 38893.927 | I40: =I39+SUM(I27:I30) -> 38886.579 | J40: =J39+SUM(J27:J30) -> 37217.923 | K40: =K39+SUM(K27:K30) -> 37045.893
A42: Balance Sheet Check | B42: =IF(ROUND(B40-B17,2)=0,"Check", "ERROR") -> Check | C42: =IF(ROUND(C40-C17,2)=0,"Check", "ERROR") -> Check | D42: =IF(ROUND(D40-D17,2)=0,"Check", "ERROR") -> Check | E42: =IF(ROUND(E40-E17,2)=0,"Check", "ERROR") -> Check | F42: =IF(ROUND(F40-F17,2)=0,"Check", "ERROR") -> Check | G42: =IF(ROUND(G40-G17,2)=0,"Check", "ERROR") -> Check | H42: =IF(ROUND(H40-H17,2)=0,"Check", "ERROR") -> Check | I42: =IF(ROUND(I40-I17,2)=0,"Check", "ERROR") -> Check | ... K42: =IF(ROUND(K40-K17,2)=0,"Check", "ERROR") -> Check
A43: Difference | B43: =B17-B40 -> 0 | C43: =C17-C40 -> 0 | D43: =D17-D40 -> 0 | E43: =E17-E40 -> 0 | F43: =F17-F40 -> 0 | G43: =G17-G40 -> 0 | H43: =H17-H40 -> 0 | I43: =I17-I40 -> 0 | ... K43: =K17-K40 -> 0
A48: Balance Sheet Assumptions/Drivers
...

Sheet Statement of Cashflows
A1: Nike Historical & Projected Cash Flow Statement
A3: (In millions, except per share data) | B3: 2022A | C3: 2023A | D3: 2024A | E3: 2025A | F3: 2026A | G3: 2027E | H3: 2028E | I3: 2029E | J3: 2030E | K3: 2031E
A4: OPERATIONS
A5: Net income | B5: 6046 | C5: 5070 | D5: 5700 | E5: 3219 | F5: 3108 | G5: ='Income statement'!I14 -> 4342.4312 | H5: ='Income statement'!J14 -> 4516.1284 | I5: ='Income statement'!K14 -> 4651.6123 | J5: ='Income statement'!L14 -> 4744.6445 | K5: ='Income statement'!M14 -> 4839.5374
A6: Adjustments to reconcile net income to net cash provided (used) by operations:
A7: Depreciation, Amortization, impairment and other | B7: 717 | C7: 703 | D7: 796 | E7: 775 | F7: 747 | G7: ='Balance Sheet'!B55*'Income statement'!I4 -> 739.8745 | H7: ='Balance Sheet'!C55*'Income statement'!J4 -> 769.46948 | I7: ='Balance Sheet'!D55*'Income statement'!K4 -> 792.55357 | J7: ='Balance Sheet'!E55*'Income statement'!L4 -> 808.40464 | K7: ='Balance Sheet'!F55*'Income statement'!M4 -> 824.57273
A8: Deferred income taxes | B8: -650 | C8: -117 | D8: -497 | E8: -288 | F8: -96 | G8: =('Balance Sheet'!G16-'Balance Sheet'!F16)*-1 -> 80.187523 | H8: =('Balance Sheet'!H16-'Balance Sheet'!G16)*-1 -> -223.7525 | I8: =('Balance Sheet'!I16-'Balance Sheet'!H16)*-1 -> -174.52695 | J8: =('Balance Sheet'!J16-'Balance Sheet'!I16)*-1 -> -119.84184 | K8: =('Balance Sheet'!K16-'Balance Sheet'!J16)*-1 -> -122.23868
A9: Stock-based compensation | B9: 638 | C9: 755 | D9: 804 | E9: 709 | F9: 715 | G9: =B46*'Income statement'!I4 -> 714.68791 | H9: =C46*'Income statement'!J4 -> 743.27543 | I9: =D46*'Income statement'!K4 -> 765.57369 | J9: =E46*'Income statement'!L4 -> 780.88516 | K9: =F46*'Income statement'!M4 -> 796.50287
A10: Net foreign currency adjustments | B10: -26 | C10: -213 | D10: -138 | E10: 37 | F10: 22 | G10: 0 | H10: 0 | I10: 0 | J10: 0 | K10: 0 | L10: Held flat at 0 in absence of a reliable method to predict currency fluctuations
A11: Changes in certain working capital components and other assets and liabilities:
A12: (Increase) decrease in accounts receivable | B12: -504 | C12: 489 | D12: -329 | E12: -257 | F12: -1207 | G12: =('Balance Sheet'!G8-'Balance Sheet'!F8)*-1 -> 1526.8876 | H12: =('Balance Sheet'!H8-'Balance Sheet'!G8)*-1 -> -176.1645 | I12: =('Balance Sheet'!I8-'Balance Sheet'!H8)*-1 -> -137.40831 | J12: =('Balance Sheet'!J8-'Balance Sheet'!I8)*-1 -> -94.353705 | K12: =('Balance Sheet'!K8-'Balance Sheet'!J8)*-1 -> -96.240779
A13: (Increase) decrease in inventories | B13: -1676 | C13: -133 | D13: 908 | E13: 120 | F13: -31 | G13: =('Balance Sheet'!G9-'Balance Sheet'!F9)*-1 -> -12.944879 | H13: =('Balance Sheet'!H9-'Balance Sheet'!G9)*-1 -> -300.5578 | I13: =('Balance Sheet'!I9-'Balance Sheet'!H9)*-1 -> -234.43508 | J13: =('Balance Sheet'!J9-'Balance Sheet'!I9)*-1 -> -160.97876 | K13: =('Balance Sheet'!K9-'Balance Sheet'!J9)*-1 -> -164.19833
A14: (Increase) decrease in prepaid expenses, operating lease right-of-use assets and other assets | B14: -845 | C14: -644 | D14: -260 | E14: -224 | F14: 519 | G14: =-1*(SUM('Balance Sheet'!G10,'Balance Sheet'!G13)-SUM('Balance Sheet'!F10,'Balance Sheet'!F13)) -> 189.06354 | H14: =-1*(SUM('Balance Sheet'!H10,'Balance Sheet'!H13)-SUM('Balance Sheet'!G10,'Balance Sheet'!G13)) -> -191.71746 | I14: =-1*(SUM('Balance Sheet'!I10,'Balance Sheet'!I13)-SUM('Balance Sheet'!H10,'Balance Sheet'!H13)) -> -149.53962 | J14: =-1*(SUM('Balance Sheet'!J10,'Balance Sheet'!J13)-SUM('Balance Sheet'!I10,'Balance Sheet'!I13)) -> -102.68387 | K14: =-1*(SUM('Balance Sheet'!K10,'Balance Sheet'!K13)-SUM('Balance Sheet'!J10,'Balance Sheet'!J13)) -> -104.73755
A15: Increase (decrease) in accounts payable, accrued liabilities, operating lease liabilities and other liabilities | B15: 1365 | C15: -225 | D15: 397 | E15: -426 | F15: -959 | G15: =SUM('Balance Sheet'!G23:G26,'Balance Sheet'!G29,'Balance Sheet'!G30)-SUM('Balance Sheet'!F23:F26,'Balance Sheet'!F29,'Balance Sheet'!F30) -> -106.80909 | H15: =SUM('Balance Sheet'!H23:H26,'Balance Sheet'!H29,'Balance Sheet'!H30)-SUM('Balance Sheet'!G23:G26,'Balance Sheet'!G29,'Balance Sheet'!G30) -> 619.84764 | I15: =SUM('Balance Sheet'!I23:I26,'Balance Sheet'!I29,'Balance Sheet'!I30)-SUM('Balance Sheet'!H23:H26,'Balance Sheet'!H29,'Balance Sheet'!H30) -> 483.48116 | J15: =SUM('Balance Sheet'!J23:J26,'Balance Sheet'!J29,'Balance Sheet'!J30)-SUM('Balance Sheet'!I23:I26,'Balance Sheet'!I29,'Balance Sheet'!I30) -> 331.99039 | K15: =SUM('Balance Sheet'!K23:K26,'Balance Sheet'!K29,'Balance Sheet'!K30)-SUM('Balance Sheet'!J23:J26,'Balance Sheet'!J29,'Balance Sheet'!J30) -> 338.6302
A16: Cash provided (used) by operations | B16: 5188 | C16: 5841 | D16: 7429 | E16: 3698 | F16: 2868 | G16: =SUM(G5:G15) -> 7473.3782 | H16: =SUM(H5:H15) -> 5756.5287 | I16: =SUM(I5:I15) -> 5997.3107 | J16: =SUM(J5:J15) -> 6188.0665 | K16: =SUM(K5:K15) -> 6311.8279
A18: INVESTING
A19: Purchases of short-term investments | B19: -12913 | C19: -6059 | D19: -4767 | E19: -3234 | F19: -1316 | G19: =('Balance Sheet'!G7-'Balance Sheet'!F7)*-1 -> -362.31737 | H19: =('Balance Sheet'!H7-'Balance Sheet'!G7)*-1 -> -451.98532 | I19: =('Balance Sheet'!I7-'Balance Sheet'!H7)*-1 -> -563.84469 | J19: =('Balance Sheet'!J7-'Balance Sheet'!I7)*-1 -> -703.38754 | K19: =('Balance Sheet'!K7-'Balance Sheet'!J7)*-1 -> -877.46508
A20: Maturities of short-term investments | B20: 8199 | C20: 3356 | D20: 2269 | E20: 319 | F20: 556 | G20: 0 | H20: 0 | I20: 0 | J20: 0 | K20: 0 | L20: Netted into Purchases of Short Term Investments
A21: Sales of short-term investments | B21: 3967 | C21: 4184 | D21: 4219 | E21: 3062 | F21: 1021 | G21: 0 | H21: 0 | I21: 0 | J21: 0 | K21: 0 | L21: Netted into Purchases of Short Term Investments
A22: Additions to property, plant and equipment | B22: -758 | C22: -969 | D22: -812 | E22: -430 | F22: -684 | G22: =('Income statement'!I4*'Balance Sheet'!B54)*-1 -> -716.6972 | H22: =('Income statement'!J4*'Balance Sheet'!C54)*-1 -> -745.36509 | I22: =('Income statement'!K4*'Balance Sheet'!D54)*-1 -> -767.72604 | J22: =('Income statement'!L4*'Balance Sheet'!E54)*-1 -> -783.08057 | K22: =('Income statement'!M4*'Balance Sheet'!F54)*-1 -> -798.74218
A23: Other investing activities | B23: -19 | C23: 52 | D23: -15 | E23: 8 | F23: -65 | G23: 0 | H23: 0 | I23: 0 | J23: 0 | K23: 0 | L23: Netted into Purchases of Short Term Investments
A24: Cash provided (used) by investing activities | B24: -1524 | C24: 564 | D24: 894 | E24: -275 | F24: -488 | G24: =SUM(G19:G23) -> -1079.0146 | H24: =SUM(H19:H23) -> -1197.3504 | I24: =SUM(I19:I23) -> -1331.5707 | J24: =SUM(J19:J23) -> -1486.4681 | K24: =SUM(K19:K23) -> -1676.2073
A26: FINANCING
A27: Proceeds from borrowings, net of debt issuance costs | B27: — | C27: — | D27: — | E27: — | F27: — | G27: — | H27: — | I27: — | J27: — | K27: —
A28: Increase (decrease) in notes payable, net | B28: 15 | C28: -4 | D28: — | E28: -1 | F28: 354 | G28: — | H28: — | I28: — | J28: — | K28: —
A29: Repayment of borrowings | B29: — | C29: -500 | D29: — | E29: -1000 | F29: — | G29: ='Balance Sheet'!B71 -> -2000 | H29: ='Balance Sheet'!C71 -> 0 | I29: ='Balance Sheet'!D71 -> 0 | J29: ='Balance Sheet'!E71 -> -1500 | K29: ='Balance Sheet'!F71 -> 0
A30: Proceeds from exercise of stock options and other stock issuances | B30: 1151 | C30: 651 | D30: 667 | E30: 551 | F30: 354 | G30: =B47*'Income statement'!I4 -> 540.02632 | H30: =C47*'Income statement'!J4 -> 561.62737 | I30: =D47*'Income statement'!K4 -> 578.4762 | J30: =E47*'Income statement'!L4 -> 590.04572 | K30: =F47*'Income statement'!M4 -> 601.84663
A31: Repurchase of common stock | B31: -4014 | C31: -5480 | D31: -4250 | E31: -2985 | F31: -146 | G31: =-1*(B48*'Income statement'!I4) -> -1911.5976 | H31: =-1*(C48*'Income statement'!J4) -> -2982.0923 | I31: =-1*(D48*'Income statement'!K4) -> -4095.4067 | J31: =-1*(E48*'Income statement'!L4) -> -4177.3148 | K31: =-1*(F48*'Income statement'!M4) -> -4260.8611
A32: Dividends — common and preferred | B32: -1837 | C32: -2012 | D32: -2169 | E32: -2300 | F32: -2407 | G32: =B49*'Income statement'!I14 -> -2232.1559 | H32: =C49*'Income statement'!J14 -> -2321.4421 | I32: =D49*'Income statement'!K14 -> -2391.0854 | J32: =E49*'Income statement'!L14 -> -2438.9071 | K32: =F49*'Income statement'!M14 -> -2487.6852
A33: Other financing activities | B33: -151 | C33: -102 | D33: -136 | E33: -85 | F33: -93 | G33: 0 | H33: 0 | I33: 0 | J33: 0 | K33: 0
A34: Cash provided (used) by financing activities | B34: -4836 | C34: -7447 | D34: -5888 | E34: -5820 | F34: -2292 | G34: =SUM(G27:G33) -> -5603.7271 | H34: =SUM(H27:H33) -> -4741.907 | I34: =SUM(I27:I33) -> -5908.0159 | J34: =SUM(J27:J33) -> -7526.1762 | K34: =SUM(K27:K33) -> -6146.6997
A36: Effect of exchange rate changes on cash and equivalents | B36: -143 | C36: -91 | D36: -16 | E36: 1 | F36: 11 | G36: 0 | H36: 0 | I36: 0 | J36: 0 | K36: 0 | L36: Held flat at 0 in absence of no reliable method of predicting currency fluctuations
A37: Net increase (decrease) in cash and equivalents | B37: -1315 | C37: -1133 | D37: 2419 | E37: -2396 | F37: 99 | G37: =SUM(G34,G24,G16) -> 790.63653 | H37: =SUM(H34,H24,H16) -> -182.72867 | I37: =SUM(I34,I24,I16) -> -1242.2759 | J37: =SUM(J34,J24,J16) -> -2824.5777 | K37: =SUM(K34,K24,K16) -> -1511.0791
A38: Cash and equivalents, beginning of year | B38: 9889 | C38: 8574 | D38: 7441 | E38: 9860 | F38: 7464 | G38: =F39 -> 7563 | H38: =G39 -> 8353.6365 | I38: =H39 -> 8170.9079 | J38: =I39 -> 6928.632 | K38: =J39 -> 4104.0543
A39: CASH AND EQUIVALENTS, END OF YEAR | B39: 8574 | C39: 7441 | D39: 9860 | E39: 7464 | F39: 7563 | G39: =SUM(G36:G38) -> 8353.6365 | H39: =SUM(H36:H38) -> 8170.9079 | I39: =SUM(I36:I38) -> 6928.632 | J39: =SUM(J36:J38) -> 4104.0543 | K39: =SUM(K36:K38) -> 2592.9752
A44: Cash Flow Statement Assumptions
B45: 2027 | C45: 2028 | D45: 2029 | E45: 2030 | F45: 2031
A46: Stock based Compensation (% of revenue) | B46: {=AVERAGE($B$9:$F$9/'Income statement'!$D$4:$H$4)} -> 0.014954777 | C46: {=AVERAGE($B$9:$F$9/'Income statement'!$D$4:$H$4)} -> 0.014954777 | D46: {=AVERAGE($B$9:$F$9/'Income statement'!$D$4:$H$4)} -> 0.014954777 | E46: {=AVERAGE($B$9:$F$9/'Income statement'!$D$4:$H$4)} -> 0.014954777 | F46: {=AVERAGE($B$9:$F$9/'Income statement'!$D$4:$H$4)} -> 0.014954777
A47: Proceeds from stock option exercises (% of revenue) | B47: 0.0113 | C47: 0.0113 | D47: 0.0113 | E47: 0.0113 | F47: 0.0113 | G47: Trailing 4 year average, ignoring 2022 outlier
A48: Share repurchases (% of revenue) | B48: 0.04 | C48: 0.06 | D48: 0.08 | E48: 0.08 | F48: 0.08 | G48: Assumes higher sales will drive up share buy back rate then remain constant
...

Sheet PB_CACHE_JS
